Workbook

Sheet Exec Summary
A1: VulnPulse — Executive Summary | D1: Period Start: | E1: 46204
A2: Source: 15 tag export file(s) | 515 hosts | 15 tags | D2: Period End: | E2: 46234
A4: 1. Flow — New / Remediated / Backlog (exact, from Created/Closed dates)
A5: Metric | B5: Count
A6: New Findings This Period | B6: =SUM(All_Findings_Raw!$S$2:$S$4274) -> 264
A7: Remediated This Period (true closes only) | B7: =SUM(All_Findings_Raw!$T$2:$T$4274) -> 254
A8: Currently Open (includes Reopened) | B8: =SUM(All_Findings_Raw!$R$2:$R$4274) -> 1817
A9: Backlog (open, predates this period) | B9: =SUMPRODUCT((All_Findings_Raw!$R$2:$R$4274=1)*(All_Findings_Raw!$H$2:$H$4274<$E$1)) -> 1696
A10: Currently Reopened (regressed findings) | B10: =SUM(All_Findings_Raw!$U$2:$U$4274) -> 221
A11: Net Change (New − Remediated) | B11: =B6-B7 -> 10
A13: 2. True Remediation Velocity & SLA Compliance
A14: Severity | B14: Avg Days to Close | C14: % Closed Within SLA | D14: Open Count | E14: SLA Breaches
A15: Critical | B15: =IFERROR(AVERAGEIFS(All_Findings_Raw!$P$2:$P$4274,All_Findings_Raw!$T$2:$T$4274,1,All_Findings_Raw!$G$2:$G$4274,A15),0) -> 11.778571 | C15: =IFERROR(SUMIFS(All_Findings_Raw!$W$2:$W$4274,All_Findings_Raw!$T$2:$T$4274,1,All_Findings_Raw!$G$2:$G$4274,A15)/SUMIFS(All_Findings_Raw!$T$2:$T$4274,All_Findings_Raw!$G$2:$G$4274,A15)*100,0) -> 72.857143 | D15: =SUMIFS(All_Findings_Raw!$R$2:$R$4274,All_Findings_Raw!$G$2:$G$4274,A15) -> 1147 | E15: =SUMIFS(All_Findings_Raw!$V$2:$V$4274,All_Findings_Raw!$G$2:$G$4274,A15) -> 1117
A16: High | B16: =IFERROR(AVERAGEIFS(All_Findings_Raw!$P$2:$P$4274,All_Findings_Raw!$T$2:$T$4274,1,All_Findings_Raw!$G$2:$G$4274,A16),0) -> 22.340659 | C16: =IFERROR(SUMIFS(All_Findings_Raw!$W$2:$W$4274,All_Findings_Raw!$T$2:$T$4274,1,All_Findings_Raw!$G$2:$G$4274,A16)/SUMIFS(All_Findings_Raw!$T$2:$T$4274,All_Findings_Raw!$G$2:$G$4274,A16)*100,0) -> 76.923077 | D16: =SUMIFS(All_Findings_Raw!$R$2:$R$4274,All_Findings_Raw!$G$2:$G$4274,A16) -> 609 | E16: =SUMIFS(All_Findings_Raw!$V$2:$V$4274,All_Findings_Raw!$G$2:$G$4274,A16) -> 574
A17: Medium | B17: =IFERROR(AVERAGEIFS(All_Findings_Raw!$P$2:$P$4274,All_Findings_Raw!$T$2:$T$4274,1,All_Findings_Raw!$G$2:$G$4274,A17),0) -> 55.217391 | C17: =IFERROR(SUMIFS(All_Findings_Raw!$W$2:$W$4274,All_Findings_Raw!$T$2:$T$4274,1,All_Findings_Raw!$G$2:$G$4274,A17)/SUMIFS(All_Findings_Raw!$T$2:$T$4274,All_Findings_Raw!$G$2:$G$4274,A17)*100,0) -> 86.956522 | D17: =SUMIFS(All_Findings_Raw!$R$2:$R$4274,All_Findings_Raw!$G$2:$G$4274,A17) -> 61 | E17: =SUMIFS(All_Findings_Raw!$V$2:$V$4274,All_Findings_Raw!$G$2:$G$4274,A17) -> 46
A18: Low | B18: =IFERROR(AVERAGEIFS(All_Findings_Raw!$P$2:$P$4274,All_Findings_Raw!$T$2:$T$4274,1,All_Findings_Raw!$G$2:$G$4274,A18),0) -> 0 | C18: =IFERROR(SUMIFS(All_Findings_Raw!$W$2:$W$4274,All_Findings_Raw!$T$2:$T$4274,1,All_Findings_Raw!$G$2:$G$4274,A18)/SUMIFS(All_Findings_Raw!$T$2:$T$4274,All_Findings_Raw!$G$2:$G$4274,A18)*100,0) -> 0 | D18: =SUMIFS(All_Findings_Raw!$R$2:$R$4274,All_Findings_Raw!$G$2:$G$4274,A18) -> 0 | E18: =SUMIFS(All_Findings_Raw!$V$2:$V$4274,All_Findings_Raw!$G$2:$G$4274,A18) -> 0

Sheet All_Findings_Raw
A1: Hostname | B1: HostType | C1: OSVersion | D1: Product | E1: CVE ID | F1: Status | G1: Severity | H1: Created Date | I1: Closed Date | J1: Base Score | K1: Tags | L1: Asset Criticality | M1: Vulnerability ID | N1: Recommended Remediations | O1: Age Days | P1: Days to Close | Q1: SLA Days | R1: Is Currently Open | S1: Is New (Period) | T1: Is Remediated (Period) | U1: Is Reopened | V1: Breached SLA (Open) | W1: Closed Within SLA | AA1: Severity | AB1: SLA Days
A2: APIGATEWAY-0105 | B2: Server | C2: RHEL 9 | D2: curl | E2: CVE-2023-38545 | F2: Closed | G2: High | H2: 46195 | I2: 46225 | J2: 7.5 | K2: API-Gateway | L2: High | M2: VULN-6749069 | N2: Schedule patch within next maintenance window; apply compensating WAF/firewall rule if delayed. | O2: ='Exec Summary'!$E$2-H2 -> 39 | P2: =IF(I2="","",I2-H2) -> 30 | Q2: =VLOOKUP(G2,$AA$2:$AB$5,2,FALSE()) -> 30 | R2: =IF(OR(F2="Open",F2="Reopened"),1,0) -> 0 | S2: =IF(AND(H2>='Exec Summary'!$E$1,H2<='Exec Summary'!$E$2),1,0) -> 0 | T2: =IF(AND(F2="Closed",I2<>"",I2>='Exec Summary'!$E$1,I2<='Exec Summary'!$E$2),1,0) -> 1 | U2: =IF(F2="Reopened",1,0) -> 0 | V2: =IF(AND(R2=1,O2>Q2),1,0) -> 0 | W2: =IF(AND(T2=1,P2<>"",P2<=Q2),1,0) -> 1 | AA2: Critical | AB2: 15
A3: APIGATEWAY-0105 | B3: Server | C3: RHEL 9 | D3: Jenkins | E3: CVE-2024-23897 | F3: Open | G3: Critical | H3: 46166 | J3: 9.8 | K3: API-Gateway | L3: High | M3: VULN-2154992 | N3: Apply vendor patch immediately; isolate host from network if patch unavailable within 24h. | O3: ='Exec Summary'!$E$2-H3 -> 68 | P3: =IF(I3="","",I3-H3) | Q3: =VLOOKUP(G3,$AA$2:$AB$5,2,FALSE()) -> 15 | R3: =IF(OR(F3="Open",F3="Reopened"),1,0) -> 1 | S3: =IF(AND(H3>='Exec Summary'!$E$1,H3<='Exec Summary'!$E$2),1,0) -> 0 | T3: =IF(AND(F3="Closed",I3<>"",I3>='Exec Summary'!$E$1,I3<='Exec Summary'!$E$2),1,0) -> 0 | U3: =IF(F3="Reopened",1,0) -> 0 | V3: =IF(AND(R3=1,O3>Q3),1,0) -> 1 | W3: =IF(AND(T3=1,P3<>"",P3<=Q3),1,0) -> 0 | AA3: High | AB3: 30
A4: APIGATEWAY-0105 | B4: Server | C4: RHEL 9 | D4: Windows Hyper-V | E4: CVE-2024-38080 | F4: Closed | G4: Critical | H4: 46051 | I4: 46063 | J4: 7.8 | K4: API-Gateway | L4: High | M4: VULN-9461748 | N4: Apply vendor patch immediately; isolate host from network if patch unavailable within 24h. | O4: ='Exec Summary'!$E$2-H4 -> 183 | P4: =IF(I4="","",I4-H4) -> 12 | Q4: =VLOOKUP(G4,$AA$2:$AB$5,2,FALSE()) -> 15 | R4: =IF(OR(F4="Open",F4="Reopened"),1,0) -> 0 | S4: =IF(AND(H4>='Exec Summary'!$E$1,H4<='Exec Summary'!$E$2),1,0) -> 0 | T4: =IF(AND(F4="Closed",I4<>"",I4>='Exec Summary'!$E$1,I4<='Exec Summary'!$E$2),1,0) -> 0 | U4: =IF(F4="Reopened",1,0) -> 0 | V4: =IF(AND(R4=1,O4>Q4),1,0) -> 0 | W4: =IF(AND(T4=1,P4<>"",P4<=Q4),1,0) -> 0 | AA4: Medium | AB4: 90
A5: APIGATEWAY-0105 | B5: Server | C5: RHEL 9 | D5: Veeam Backup | E5: CVE-2024-29849 | F5: Open | G5: High | H5: 46148 | J5: 8.1 | K5: API-Gateway | L5: High | M5: VULN-2615622 | N5: Schedule patch within next maintenance window; apply compensating WAF/firewall rule if delayed. | O5: ='Exec Summary'!$E$2-H5 -> 86 | P5: =IF(I5="","",I5-H5) | Q5: =VLOOKUP(G5,$AA$2:$AB$5,2,FALSE()) -> 30 | R5: =IF(OR(F5="Open",F5="Reopened"),1,0) -> 1 | S5: =IF(AND(H5>='Exec Summary'!$E$1,H5<='Exec Summary'!$E$2),1,0) -> 0 | T5: =IF(AND(F5="Closed",I5<>"",I5>='Exec Summary'!$E$1,I5<='Exec Summary'!$E$2),1,0) -> 0 | U5: =IF(F5="Reopened",1,0) -> 0 | V5: =IF(AND(R5=1,O5>Q5),1,0) -> 1 | W5: =IF(AND(T5=1,P5<>"",P5<=Q5),1,0) -> 0 | AA5: Low | AB5: 180
A6: APIGATEWAY-0105 | B6: Server | C6: RHEL 9 | D6: FortiOS SSL-VPN | E6: CVE-2023-27997 | F6: Closed | G6: Critical | H6: 46024 | I6: 46036 | J6: 9.8 | K6: API-Gateway | L6: High | M6: VULN-1654924 | N6: Apply vendor patch immediately; isolate host from network if patch unavailable within 24h. | O6: ='Exec Summary'!$E$2-H6 -> 210 | P6: =IF(I6="","",I6-H6) -> 12 | Q6: =VLOOKUP(G6,$AA$2:$AB$5,2,FALSE()) -> 15 | R6: =IF(OR(F6="Open",F6="Reopened"),1,0) -> 0 | S6: =IF(AND(H6>='Exec Summary'!$E$1,H6<='Exec Summary'!$E$2),1,0) -> 0 | T6: =IF(AND(F6="Closed",I6<>"",I6>='Exec Summary'!$E$1,I6<='Exec Summary'!$E$2),1,0) -> 0 | U6: =IF(F6="Reopened",1,0) -> 0 | V6: =IF(AND(R6=1,O6>Q6),1,0) -> 0 | W6: =IF(AND(T6=1,P6<>"",P6<=Q6),1,0) -> 0
A7: APIGATEWAY-0105 | B7: Server | C7: RHEL 9 | D7: JetBrains TeamCity | E7: CVE-2024-27198 | F7: Closed | G7: Critical | H7: 46206 | I7: 46222 | J7: 9.8 | K7: API-Gateway | L7: High | M7: VULN-1020136 | N7: Apply vendor patch immediately; isolate host from network if patch unavailable within 24h. | O7: ='Exec Summary'!$E$2-H7 -> 28 | P7: =IF(I7="","",I7-H7) -> 16 | Q7: =VLOOKUP(G7,$AA$2:$AB$5,2,FALSE()) -> 15 | R7: =IF(OR(F7="Open",F7="Reopened"),1,0) -> 0 | S7: =IF(AND(H7>='Exec Summary'!$E$1,H7<='Exec Summary'!$E$2),1,0) -> 1 | T7: =IF(AND(F7="Closed",I7<>"",I7>='Exec Summary'!$E$1,I7<='Exec Summary'!$E$2),1,0) -> 1 | U7: =IF(F7="Reopened",1,0) -> 0 | V7: =IF(AND(R7=1,O7>Q7),1,0) -> 0 | W7: =IF(AND(T7=1,P7<>"",P7<=Q7),1,0) -> 0
A8: APIGATEWAY-0105 | B8: Server | C8: RHEL 9 | D8: MOVEit Transfer | E8: CVE-2023-34362 | F8: Closed | G8: Critical | H8: 46154 | I8: 46170 | J8: 9.8 | K8: API-Gateway | L8: High | M8: VULN-1728773 | N8: Apply vendor patch immediately; isolate host from network if patch unavailable within 24h. | O8: ='Exec Summary'!$E$2-H8 -> 80 | P8: =IF(I8="","",I8-H8) -> 16 | Q8: =VLOOKUP(G8,$AA$2:$AB$5,2,FALSE()) -> 15 | R8: =IF(OR(F8="Open",F8="Reopened"),1,0) -> 0 | S8: =IF(AND(H8>='Exec Summary'!$E$1,H8<='Exec Summary'!$E$2),1,0) -> 0 | T8: =IF(AND(F8="Closed",I8<>"",I8>='Exec Summary'!$E$1,I8<='Exec Summary'!$E$2),1,0) -> 0 | U8: =IF(F8="Reopened",1,0) -> 0 | V8: =IF(AND(R8=1,O8>Q8),1,0) -> 0 | W8: =IF(AND(T8=1,P8<>"",P8<=Q8),1,0) -> 0
A9: APIGATEWAY-0105 | B9: Server | C9: RHEL 9 | D9: Microsoft Exchange Server | E9: CVE-2024-49040 | F9: Closed | G9: Medium | H9: 46205 | I9: 46234 | J9: 6.5 | K9: API-Gateway | L9: High | M9: VULN-6880713 | N9: Include in next scheduled patch cycle. | O9: ='Exec Summary'!$E$2-H9 -> 29 | P9: =IF(I9="","",I9-H9) -> 29 | Q9: =VLOOKUP(G9,$AA$2:$AB$5,2,FALSE()) -> 90 | R9: =IF(OR(F9="Open",F9="Reopened"),1,0) -> 0 | S9: =IF(AND(H9>='Exec Summary'!$E$1,H9<='Exec Summary'!$E$2),1,0) -> 1 | T9: =IF(AND(F9="Closed",I9<>"",I9>='Exec Summary'!$E$1,I9<='Exec Summary'!$E$2),1,0) -> 1 | U9: =IF(F9="Reopened",1,0) -> 0 | V9: =IF(AND(R9=1,O9>Q9),1,0) -> 0 | W9: =IF(AND(T9=1,P9<>"",P9<=Q9),1,0) -> 1
A10: APIGATEWAY-0106 | B10: Server | C10: Windows Server 2022 | D10: Jenkins | E10: CVE-2024-23897 | F10: Closed | G10: Critical | H10: 45994 | I10: 46002 | J10: 9.8 | K10: API-Gateway | L10: Medium | M10: VULN-4446353 | N10: Apply vendor patch immediately; isolate host from network if patch unavailable within 24h. | O10: ='Exec Summary'!$E$2-H10 -> 240 | P10: =IF(I10="","",I10-H10) -> 8 | Q10: =VLOOKUP(G10,$AA$2:$AB$5,2,FALSE()) -> 15 | R10: =IF(OR(F10="Open",F10="Reopened"),1,0) -> 0 | S10: =IF(AND(H10>='Exec Summary'!$E$1,H10<='Exec Summary'!$E$2),1,0) -> 0 | T10: =IF(AND(F10="Closed",I10<>"",I10>='Exec Summary'!$E$1,I10<='Exec Summary'!$E$2),1,0) -> 0 | U10: =IF(F10="Reopened",1,0) -> 0 | V10: =IF(AND(R10=1,O10>Q10),1,0) -> 0 | W10: =IF(AND(T10=1,P10<>"",P10<=Q10),1,0) -> 0
A11: APIGATEWAY-0106 | B11: Server | C11: Windows Server 2022 | D11: Windows Common Log File System Driver | E11: CVE-2024-49138 | F11: Closed | G11: High | H11: 46095 | I11: 46128 | J11: 7.8 | K11: API-Gateway | L11: Medium | M11: VULN-5383935 | N11: Schedule patch within next maintenance window; apply compensating WAF/firewall rule if delayed. | O11: ='Exec Summary'!$E$2-H11 -> 139 | P11: =IF(I11="","",I11-H11) -> 33 | Q11: =VLOOKUP(G11,$AA$2:$AB$5,2,FALSE()) -> 30 | R11: =IF(OR(F11="Open",F11="Reopened"),1,0) -> 0 | S11: =IF(AND(H11>='Exec Summary'!$E$1,H11<='Exec Summary'!$E$2),1,0) -> 0 | T11: =IF(AND(F11="Closed",I11<>"",I11>='Exec Summary'!$E$1,I11<='Exec Summary'!$E$2),1,0) -> 0 | U11: =IF(F11="Reopened",1,0) -> 0 | V11: =IF(AND(R11=1,O11>Q11),1,0) -> 0 | W11: =IF(AND(T11=1,P11<>"",P11<=Q11),1,0) -> 0
A12: APIGATEWAY-0106 | B12: Server | C12: Windows Server 2022 | D12: nginx | E12: CVE-2023-44487 | F12: Closed | G12: High | H12: 46208 | I12: 46234 | J12: 7.5 | K12: API-Gateway | L12: Medium | M12: VULN-5623138 | N12: Schedule patch within next maintenance window; apply compensating WAF/firewall rule if delayed. | O12: ='Exec Summary'!$E$2-H12 -> 26 | P12: =IF(I12="","",I12-H12) -> 26 | Q12: =VLOOKUP(G12,$AA$2:$AB$5,2,FALSE()) -> 30 | R12: =IF(OR(F12="Open",F12="Reopened"),1,0) -> 0 | S12: =IF(AND(H12>='Exec Summary'!$E$1,H12<='Exec Summary'!$E$2),1,0) -> 1 | T12: =IF(AND(F12="Closed",I12<>"",I12>='Exec Summary'!$E$1,I12<='Exec Summary'!$E$2),1,0) -> 1 | U12: =IF(F12="Reopened",1,0) -> 0 | V12: =IF(AND(R12=1,O12>Q12),1,0) -> 0 | W12: =IF(AND(T12=1,P12<>"",P12<=Q12),1,0) -> 1
A13: APIGATEWAY-0106 | B13: Server | C13: Windows Server 2022 | D13: PAN-OS | E13: CVE-2024-3400 | F13: Open | G13: Critical | H13: 46137 | J13: 10 | K13: API-Gateway | L13: Medium | M13: VULN-7932818 | N13: Apply vendor patch immediately; isolate host from network if patch unavailable within 24h. | O13: ='Exec Summary'!$E$2-H13 -> 97 | P13: =IF(I13="","",I13-H13) | Q13: =VLOOKUP(G13,$AA$2:$AB$5,2,FALSE()) -> 15 | R13: =IF(OR(F13="Open",F13="Reopened"),1,0) -> 1 | S13: =IF(AND(H13>='Exec Summary'!$E$1,H13<='Exec Summary'!$E$2),1,0) -> 0 | T13: =IF(AND(F13="Closed",I13<>"",I13>='Exec Summary'!$E$1,I13<='Exec Summary'!$E$2),1,0) -> 0 | U13: =IF(F13="Reopened",1,0) -> 0 | V13: =IF(AND(R13=1,O13>Q13),1,0) -> 1 | W13: =IF(AND(T13=1,P13<>"",P13<=Q13),1,0) -> 0
A14: APIGATEWAY-0106 | B14: Server | C14: Windows Server 2022 | D14: FortiOS SSL-VPN | E14: CVE-2023-27997 | F14: Open | G14: Critical | H14: 46216 | J14: 9.8 | K14: API-Gateway | L14: Medium | M14: VULN-9094465 | N14: Apply vendor patch immediately; isolate host from network if patch unavailable within 24h. | O14: ='Exec Summary'!$E$2-H14 -> 18 | P14: =IF(I14="","",I14-H14) | Q14: =VLOOKUP(G14,$AA$2:$AB$5,2,FALSE()) -> 15 | R14: =IF(OR(F14="Open",F14="Reopened"),1,0) -> 1 | S14: =IF(AND(H14>='Exec Summary'!$E$1,H14<='Exec Summary'!$E$2),1,0) -> 1 | T14: =IF(AND(F14="Closed",I14<>"",I14>='Exec Summary'!$E$1,I14<='Exec Summary'!$E$2),1,0) -> 0 | U14: =IF(F14="Reopened",1,0) -> 0 | V14: =IF(AND(R14=1,O14>Q14),1,0) -> 1 | W14: =IF(AND(T14=1,P14<>"",P14<=Q14),1,0) -> 0
A15: APIGATEWAY-0106 | B15: Server | C15: Windows Server 2022 | D15: MySQL | E15: CVE-2024-6670 | F15: Closed | G15: High | H15: 46025 | I15: 46037 | J15: 8.1 | K15: API-Gateway | L15: Medium | M15: VULN-6777340 | N15: Schedule patch within next maintenance window; apply compensating WAF/firewall rule if delayed. | O15: ='Exec Summary'!$E$2-H15 -> 209 | P15: =IF(I15="","",I15-H15) -> 12 | Q15: =VLOOKUP(G15,$AA$2:$AB$5,2,FALSE()) -> 30 | R15: =IF(OR(F15="Open",F15="Reopened"),1,0) -> 0 | S15: =IF(AND(H15>='Exec Summary'!$E$1,H15<='Exec Summary'!$E$2),1,0) -> 0 | T15: =IF(AND(F15="Closed",I15<>"",I15>='Exec Summary'!$E$1,I15<='Exec Summary'!$E$2),1,0) -> 0 | U15: =IF(F15="Reopened",1,0) -> 0 | V15: =IF(AND(R15=1,O15>Q15),1,0) -> 0 | W15: =IF(AND(T15=1,P15<>"",P15<=Q15),1,0) -> 0
A16: APIGATEWAY-0106 | B16: Server | C16: Windows Server 2022 | D16: Veeam Backup | E16: CVE-2024-29849 | F16: Open | G16: High | H16: 46137 | J16: 8.1 | K16: API-Gateway | L16: Medium | M16: VULN-2997927 | N16: Schedule patch within next maintenance window; apply compensating WAF/firewall rule if delayed. | O16: ='Exec Summary'!$E$2-H16 -> 97 | P16: =IF(I16="","",I16-H16) | Q16: =VLOOKUP(G16,$AA$2:$AB$5,2,FALSE()) -> 30 | R16: =IF(OR(F16="Open",F16="Reopened"),1,0) -> 1 | S16: =IF(AND(H16>='Exec Summary'!$E$1,H16<='Exec Summary'!$E$2),1,0) -> 0 | T16: =IF(AND(F16="Closed",I16<>"",I16>='Exec Summary'!$E$1,I16<='Exec Summary'!$E$2),1,0) -> 0 | U16: =IF(F16="Reopened",1,0) -> 0 | V16: =IF(AND(R16=1,O16>Q16),1,0) -> 1 | W16: =IF(AND(T16=1,P16<>"",P16<=Q16),1,0) -> 0
A17: APIGATEWAY-0106 | B17: Server | C17: Windows Server 2022 | D17: libwebp | E17: CVE-2023-4863 | F17: Closed | G17: High | H17: 46051 | I17: 46070 | J17: 8.8 | K17: API-Gateway | L17: Medium | M17: VULN-3714471 | N17: Schedule patch within next maintenance window; apply compensating WAF/firewall rule if delayed. | O17: ='Exec Summary'!$E$2-H17 -> 183 | P17: =IF(I17="","",I17-H17) -> 19 | Q17: =VLOOKUP(G17,$AA$2:$AB$5,2,FALSE()) -> 30 | R17: =IF(OR(F17="Open",F17="Reopened"),1,0) -> 0 | S17: =IF(AND(H17>='Exec Summary'!$E$1,H17<='Exec Summary'!$E$2),1,0) -> 0 | T17: =IF(AND(F17="Closed",I17<>"",I17>='Exec Summary'!$E$1,I17<='Exec Summary'!$E$2),1,0) -> 0 | U17: =IF(F17="Reopened",1,0) -> 0 | V17: =IF(AND(R17=1,O17>Q17),1,0) -> 0 | W17: =IF(AND(T17=1,P17<>"",P17<=Q17),1,0) -> 0
A18: APIGATEWAY-0106 | B18: Server | C18: Windows Server 2022 | D18: ConnectWise ScreenConnect | E18: CVE-2024-1709 | F18: Closed | G18: Critical | H18: 45985 | I18: 45991 | J18: 10 | K18: API-Gateway | L18: Medium | M18: VULN-1873301 | N18: Apply vendor patch immediately; isolate host from network if patch unavailable within 24h. | O18: ='Exec Summary'!$E$2-H18 -> 249 | P18: =IF(I18="","",I18-H18) -> 6 | Q18: =VLOOKUP(G18,$AA$2:$AB$5,2,FALSE()) -> 15 | R18: =IF(OR(F18="Open",F18="Reopened"),1,0) -> 0 | S18: =IF(AND(H18>='Exec Summary'!$E$1,H18<='Exec Summary'!$E$2),1,0) -> 0 | T18: =IF(AND(F18="Closed",I18<>"",I18>='Exec Summary'!$E$1,I18<='Exec Summary'!$E$2),1,0) -> 0 | U18: =IF(F18="Reopened",1,0) -> 0 | V18: =IF(AND(R18=1,O18>Q18),1,0) -> 0 | W18: =IF(AND(T18=1,P18<>"",P18<=Q18),1,0) -> 0
A19: APIGATEWAY-0106 | B19: Server | C19: Windows Server 2022 | D19: xz-utils | E19: CVE-2024-3094 | F19: Closed | G19: Critical | H19: 46016 | I19: 46030 | J19: 10 | K19: API-Gateway | L19: Medium | M19: VULN-2528212 | N19: Apply vendor patch immediately; isolate host from network if patch unavailable within 24h. | O19: ='Exec Summary'!$E$2-H19 -> 218 | P19: =IF(I19="","",I19-H19) -> 14 | Q19: =VLOOKUP(G19,$AA$2:$AB$5,2,FALSE()) -> 15 | R19: =IF(OR(F19="Open",F19="Reopened"),1,0) -> 0 | S19: =IF(AND(H19>='Exec Summary'!$E$1,H19<='Exec Summary'!$E$2),1,0) -> 0 | T19: =IF(AND(F19="Closed",I19<>"",I19>='Exec Summary'!$E$1,I19<='Exec Summary'!$E$2),1,0) -> 0 | U19: =IF(F19="Reopened",1,0) -> 0 | V19: =IF(AND(R19=1,O19>Q19),1,0) -> 0 | W19: =IF(AND(T19=1,P19<>"",P19<=Q19),1,0) -> 0
A20: APIGATEWAY-0106 | B20: Server | C20: Windows Server 2022 | D20: Spring Framework | E20: CVE-2022-22965 | F20: Closed | G20: Critical | H20: 46008 | I20: 46016 | J20: 9.8 | K20: API-Gateway | L20: Medium | M20: VULN-7221581 | N20: Apply vendor patch immediately; isolate host from network if patch unavailable within 24h. | O20: ='Exec Summary'!$E$2-H20 -> 226 | P20: =IF(I20="","",I20-H20) -> 8 | Q20: =VLOOKUP(G20,$AA$2:$AB$5,2,FALSE()) -> 15 | R20: =IF(OR(F20="Open",F20="Reopened"),1,0) -> 0 | S20: =IF(AND(H20>='Exec Summary'!$E$1,H20<='Exec Summary'!$E$2),1,0) -> 0 | T20: =IF(AND(F20="Closed",I20<>"",I20>='Exec Summary'!$E$1,I20<='Exec Summary'!$E$2),1,0) -> 0 | U20: =IF(F20="Reopened",1,0) -> 0 | V20: =IF(AND(R20=1,O20>Q20),1,0) -> 0 | W20: =IF(AND(T20=1,P20<>"",P20<=Q20),1,0) -> 0
A21: APIGATEWAY-0106 | B21: Server | C21: Windows Server 2022 | D21: MOVEit Transfer | E21: CVE-2023-34362 | F21: Open | G21: Critical | H21: 45974 | J21: 9.8 | K21: API-Gateway | L21: Medium | M21: VULN-7447920 | N21: Apply vendor patch immediately; isolate host from network if patch unavailable within 24h. | O21: ='Exec Summary'!$E$2-H21 -> 260 | P21: =IF(I21="","",I21-H21) | Q21: =VLOOKUP(G21,$AA$2:$AB$5,2,FALSE()) -> 15 | R21: =IF(OR(F21="Open",F21="Reopened"),1,0) -> 1 | S21: =IF(AND(H21>='Exec Summary'!$E$1,H21<='Exec Summary'!$E$2),1,0) -> 0 | T21: =IF(AND(F21="Closed",I21<>"",I21>='Exec Summary'!$E$1,I21<='Exec Summary'!$E$2),1,0) -> 0 | U21: =IF(F21="Reopened",1,0) -> 0 | V21: =IF(AND(R21=1,O21>Q21),1,0) -> 1 | W21: =IF(AND(T21=1,P21<>"",P21<=Q21),1,0) -> 0
A22: APIGATEWAY-0106 | B22: Server | C22: Windows Server 2022 | D22: VMware Aria Operations | E22: CVE-2023-20887 | F22: Open | G22: High | H22: 46139 | J22: 8.6 | K22: API-Gateway | L22: Medium | M22: VULN-9741022 | N22: Schedule patch within next maintenance window; apply compensating WAF/firewall rule if delayed. | O22: ='Exec Summary'!$E$2-H22 -> 95 | P22: =IF(I22="","",I22-H22) | Q22: =VLOOKUP(G22,$AA$2:$AB$5,2,FALSE()) -> 30 | R22: =IF(OR(F22="Open",F22="Reopened"),1,0) -> 1 | S22: =IF(AND(H22>='Exec Summary'!$E$1,H22<='Exec Summary'!$E$2),1,0) -> 0 | T22: =IF(AND(F22="Closed",I22<>"",I22>='Exec Summary'!$E$1,I22<='Exec Summary'!$E$2),1,0) -> 0 | U22: =IF(F22="Reopened",1,0) -> 0 | V22: =IF(AND(R22=1,O22>Q22),1,0) -> 1 | W22: =IF(AND(T22=1,P22<>"",P22<=Q22),1,0) -> 0
A23: APIGATEWAY-0107 | B23: Server | C23: Windows Server 2022 | D23: Microsoft Office | E23: CVE-2023-36884 | F23: Open | G23: High | H23: 45951 | J23: 7.8 | K23: API-Gateway | L23: Medium | M23: VULN-9565571 | N23: Schedule patch within next maintenance window; apply compensating WAF/firewall rule if delayed. | O23: ='Exec Summary'!$E$2-H23 -> 283 | P23: =IF(I23="","",I23-H23) | Q23: =VLOOKUP(G23,$AA$2:$AB$5,2,FALSE()) -> 30 | R23: =IF(OR(F23="Open",F23="Reopened"),1,0) -> 1 | S23: =IF(AND(H23>='Exec Summary'!$E$1,H23<='Exec Summary'!$E$2),1,0) -> 0 | T23: =IF(AND(F23="Closed",I23<>"",I23>='Exec Summary'!$E$1,I23<='Exec Summary'!$E$2),1,0) -> 0 | U23: =IF(F23="Reopened",1,0) -> 0 | V23: =IF(AND(R23=1,O23>Q23),1,0) -> 1 | W23: =IF(AND(T23=1,P23<>"",P23<=Q23),1,0) -> 0
A24: APIGATEWAY-0107 | B24: Server | C24: Windows Server 2022 | D24: xz-utils | E24: CVE-2024-3094 | F24: Open | G24: Critical | H24: 46198 | J24: 10 | K24: API-Gateway | L24: Medium | M24: VULN-3843451 | N24: Apply vendor patch immediately; isolate host from network if patch unavailable within 24h. | O24: ='Exec Summary'!$E$2-H24 -> 36 | P24: =IF(I24="","",I24-H24) | Q24: =VLOOKUP(G24,$AA$2:$AB$5,2,FALSE()) -> 15 | R24: =IF(OR(F24="Open",F24="Reopened"),1,0) -> 1 | S24: =IF(AND(H24>='Exec Summary'!$E$1,H24<='Exec Summary'!$E$2),1,0) -> 0 | T24: =IF(AND(F24="Closed",I24<>"",I24>='Exec Summary'!$E$1,I24<='Exec Summary'!$E$2),1,0) -> 0 | U24: =IF(F24="Reopened",1,0) -> 0 | V24: =IF(AND(R24=1,O24>Q24),1,0) -> 1 | W24: =IF(AND(T24=1,P24<>"",P24<=Q24),1,0) -> 0
A25: APIGATEWAY-0107 | B25: Server | C25: Windows Server 2022 | D25: ConnectWise ScreenConnect | E25: CVE-2024-1709 | F25: Closed | G25: Critical | H25: 45952 | I25: 45961 | J25: 10 | K25: API-Gateway | L25: Medium | M25: VULN-3641484 | N25: Apply vendor patch immediately; isolate host from network if patch unavailable within 24h. | O25: ='Exec Summary'!$E$2-H25 -> 282 | P25: =IF(I25="","",I25-H25) -> 9 | Q25: =VLOOKUP(G25,$AA$2:$AB$5,2,FALSE()) -> 15 | R25: =IF(OR(F25="Open",F25="Reopened"),1,0) -> 0 | S25: =IF(AND(H25>='Exec Summary'!$E$1,H25<='Exec Summary'!$E$2),1,0) -> 0 | T25: =IF(AND(F25="Closed",I25<>"",I25>='Exec Summary'!$E$1,I25<='Exec Summary'!$E$2),1,0) -> 0 | U25: =IF(F25="Reopened",1,0) -> 0 | V25: =IF(AND(R25=1,O25>Q25),1,0) -> 0 | W25: =IF(AND(T25=1,P25<>"",P25<=Q25),1,0) -> 0
A26: APIGATEWAY-0107 | B26: Server | C26: Windows Server 2022 | D26: Apache Log4j | E26: CVE-2021-44228 | F26: Open | G26: Critical | H26: 45978 | J26: 10 | K26: API-Gateway | L26: Medium | M26: VULN-7701385 | N26: Apply vendor patch immediately; isolate host from network if patch unavailable within 24h. | O26: ='Exec Summary'!$E$2-H26 -> 256 | P26: =IF(I26="","",I26-H26) | Q26: =VLOOKUP(G26,$AA$2:$AB$5,2,FALSE()) -> 15 | R26: =IF(OR(F26="Open",F26="Reopened"),1,0) -> 1 | S26: =IF(AND(H26>='Exec Summary'!$E$1,H26<='Exec Summary'!$E$2),1,0) -> 0 | T26: =IF(AND(F26="Closed",I26<>"",I26>='Exec Summary'!$E$1,I26<='Exec Summary'!$E$2),1,0) -> 0 | U26: =IF(F26="Reopened",1,0) -> 0 | V26: =IF(AND(R26=1,O26>Q26),1,0) -> 1 | W26: =IF(AND(T26=1,P26<>"",P26<=Q26),1,0) -> 0
A27: APIGATEWAY-0107 | B27: Server | C27: Windows Server 2022 | D27: Windows Wi-Fi Driver | E27: CVE-2024-30078 | F27: Open | G27: Critical | H27: 46114 | J27: 8.8 | K27: API-Gateway | L27: Medium | M27: VULN-7802338 | N27: Apply vendor patch immediately; isolate host from network if patch unavailable within 24h. | O27: ='Exec Summary'!$E$2-H27 -> 120 | P27: =IF(I27="","",I27-H27) | Q27: =VLOOKUP(G27,$AA$2:$AB$5,2,FALSE()) -> 15 | R27: =IF(OR(F27="Open",F27="Reopened"),1,0) -> 1 | S27: =IF(AND(H27>='Exec Summary'!$E$1,H27<='Exec Summary'!$E$2),1,0) -> 0 | T27: =IF(AND(F27="Closed",I27<>"",I27>='Exec Summary'!$E$1,I27<='Exec Summary'!$E$2),1,0) -> 0 | U27: =IF(F27="Reopened",1,0) -> 0 | V27: =IF(AND(R27=1,O27>Q27),1,0) -> 1 | W27: =IF(AND(T27=1,P27<>"",P27<=Q27),1,0) -> 0
A28: APIGATEWAY-0107 | B28: Server | C28: Windows Server 2022 | D28: VMware Aria Operations | E28: CVE-2023-20887 | F28: Reopened | G28: High | H28: 46036 | I28: 46058 | J28: 8.6 | K28: API-Gateway | L28: Medium | M28: VULN-5773013 | N28: Schedule patch within next maintenance window; apply compensating WAF/firewall rule if delayed. | O28: ='Exec Summary'!$E$2-H28 -> 198 | P28: =IF(I28="","",I28-H28) -> 22 | Q28: =VLOOKUP(G28,$AA$2:$AB$5,2,FALSE()) -> 30 | R28: =IF(OR(F28="Open",F28="Reopened"),1,0) -> 1 | S28: =IF(AND(H28>='Exec Summary'!$E$1,H28<='Exec Summary'!$E$2),1,0) -> 0 | T28: =IF(AND(F28="Closed",I28<>"",I28>='Exec Summary'!$E$1,I28<='Exec Summary'!$E$2),1,0) -> 0 | U28: =IF(F28="Reopened",1,0) -> 1 | V28: =IF(AND(R28=1,O28>Q28),1,0) -> 1 | W28: =IF(AND(T28=1,P28<>"",P28<=Q28),1,0) -> 0
A29: APIGATEWAY-0107 | B29: Server | C29: Windows Server 2022 | D29: PAN-OS | E29: CVE-2024-3400 | F29: Open | G29: Critical | H29: 46220 | J29: 10 | K29: API-Gateway | L29: Medium | M29: VULN-6840069 | N29: Apply vendor patch immediately; isolate host from network if patch unavailable within 24h. | O29: ='Exec Summary'!$E$2-H29 -> 14 | P29: =IF(I29="","",I29-H29) | Q29: =VLOOKUP(G29,$AA$2:$AB$5,2,FALSE()) -> 15 | R29: =IF(OR(F29="Open",F29="Reopened"),1,0) -> 1 | S29: =IF(AND(H29>='Exec Summary'!$E$1,H29<='Exec Summary'!$E$2),1,0) -> 1 | T29: =IF(AND(F29="Closed",I29<>"",I29>='Exec Summary'!$E$1,I29<='Exec Summary'!$E$2),1,0) -> 0 | U29: =IF(F29="Reopened",1,0) -> 0 | V29: =IF(AND(R29=1,O29>Q29),1,0) -> 0 | W29: =IF(AND(T29=1,P29<>"",P29<=Q29),1,0) -> 0
A30: APIGATEWAY-0107 | B30: Server | C30: Windows Server 2022 | D30: Windows Common Log File System Driver | E30: CVE-2024-49138 | F30: Open | G30: High | H30: 46111 | J30: 7.8 | K30: API-Gateway | L30: Medium | M30: VULN-5639031 | N30: Schedule patch within next maintenance window; apply compensating WAF/firewall rule if delayed. | O30: ='Exec Summary'!$E$2-H30 -> 123 | P30: =IF(I30="","",I30-H30) | Q30: =VLOOKUP(G30,$AA$2:$AB$5,2,FALSE()) -> 30 | R30: =IF(OR(F30="Open",F30="Reopened"),1,0) -> 1 | S30: =IF(AND(H30>='Exec Summary'!$E$1,H30<='Exec Summary'!$E$2),1,0) -> 0 | T30: =IF(AND(F30="Closed",I30<>"",I30>='Exec Summary'!$E$1,I30<='Exec Summary'!$E$2),1,0) -> 0 | U30: =IF(F30="Reopened",1,0) -> 0 | V30: =IF(AND(R30=1,O30>Q30),1,0) -> 1 | W30: =IF(AND(T30=1,P30<>"",P30<=Q30),1,0) -> 0
A31: APIGATEWAY-0108 | B31: Server | C31: RHEL 8 | D31: Veeam Backup | E31: CVE-2024-29849 | F31: Closed | G31: High | H31: 46220 | I31: 46234 | J31: 8.1 | K31: API-Gateway | L31: Medium | M31: VULN-2963085 | N31: Schedule patch within next maintenance window; apply compensating WAF/firewall rule if delayed. | O31: ='Exec Summary'!$E$2-H31 -> 14 | P31: =IF(I31="","",I31-H31) -> 14 | Q31: =VLOOKUP(G31,$AA$2:$AB$5,2,FALSE()) -> 30 | R31: =IF(OR(F31="Open",F31="Reopened"),1,0) -> 0 | S31: =IF(AND(H31>='Exec Summary'!$E$1,H31<='Exec Summary'!$E$2),1,0) -> 1 | T31: =IF(AND(F31="Closed",I31<>"",I31>='Exec Summary'!$E$1,I31<='Exec Summary'!$E$2),1,0) -> 1 | U31: =IF(F31="Reopened",1,0) -> 0 | V31: =IF(AND(R31=1,O31>Q31),1,0) -> 0 | W31: =IF(AND(T31=1,P31<>"",P31<=Q31),1,0) -> 1
A32: APIGATEWAY-0108 | B32: Server | C32: RHEL 8 | D32: VMware Aria Operations | E32: CVE-2023-20887 | F32: Open | G32: High | H32: 46196 | J32: 8.6 | K32: API-Gateway | L32: Medium | M32: VULN-5196677 | N32: Schedule patch within next maintenance window; apply compensating WAF/firewall rule if delayed. | O32: ='Exec Summary'!$E$2-H32 -> 38 | P32: =IF(I32="","",I32-H32) | Q32: =VLOOKUP(G32,$AA$2:$AB$5,2,FALSE()) -> 30 | R32: =IF(OR(F32="Open",F32="Reopened"),1,0) -> 1 | S32: =IF(AND(H32>='Exec Summary'!$E$1,H32<='Exec Summary'!$E$2),1,0) -> 0 | T32: =IF(AND(F32="Closed",I32<>"",I32>='Exec Summary'!$E$1,I32<='Exec Summary'!$E$2),1,0) -> 0 | U32: =IF(F32="Reopened",1,0) -> 0 | V32: =IF(AND(R32=1,O32>Q32),1,0) -> 1 | W32: =IF(AND(T32=1,P32<>"",P32<=Q32),1,0) -> 0
A33: APIGATEWAY-0108 | B33: Server | C33: RHEL 8 | D33: Microsoft Outlook | E33: CVE-2024-21413 | F33: Open | G33: Critical | H33: 46160 | J33: 9.8 | K33: API-Gateway | L33: Medium | M33: VULN-9113963 | N33: Apply vendor patch immediately; isolate host from network if patch unavailable within 24h. | O33: ='Exec Summary'!$E$2-H33 -> 74 | P33: =IF(I33="","",I33-H33) | Q33: =VLOOKUP(G33,$AA$2:$AB$5,2,FALSE()) -> 15 | R33: =IF(OR(F33="Open",F33="Reopened"),1,0) -> 1 | S33: =IF(AND(H33>='Exec Summary'!$E$1,H33<='Exec Summary'!$E$2),1,0) -> 0 | T33: =IF(AND(F33="Closed",I33<>"",I33>='Exec Summary'!$E$1,I33<='Exec Summary'!$E$2),1,0) -> 0 | U33: =IF(F33="Reopened",1,0) -> 0 | V33: =IF(AND(R33=1,O33>Q33),1,0) -> 1 | W33: =IF(AND(T33=1,P33<>"",P33<=Q33),1,0) -> 0
A34: APIGATEWAY-0109 | B34: Workstation | C34: Windows 11 | D34: Windows Common Log File System Driver | E34: CVE-2024-49138 | F34: Closed | G34: High | H34: 46095 | I34: 46107 | J34: 7.8 | K34: API-Gateway | L34: Low | M34: VULN-5418274 | N34: Schedule patch within next maintenance window; apply compensating WAF/firewall rule if delayed. | O34: ='Exec Summary'!$E$2-H34 -> 139 | P34: =IF(I34="","",I34-H34) -> 12 | Q34: =VLOOKUP(G34,$AA$2:$AB$5,2,FALSE()) -> 30 | R34: =IF(OR(F34="Open",F34="Reopened"),1,0) -> 0 | S34: =IF(AND(H34>='Exec Summary'!$E$1,H34<='Exec Summary'!$E$2),1,0) -> 0 | T34: =IF(AND(F34="Closed",I34<>"",I34>='Exec Summary'!$E$1,I34<='Exec Summary'!$E$2),1,0) -> 0 | U34: =IF(F34="Reopened",1,0) -> 0 | V34: =IF(AND(R34=1,O34>Q34),1,0) -> 0 | W34: =IF(AND(T34=1,P34<>"",P34<=Q34),1,0) -> 0
A35: APIGATEWAY-0109 | B35: Workstation | C35: Windows 11 | D35: xz-utils | E35: CVE-2024-3094 | F35: Closed | G35: Critical | H35: 46061 | I35: 46078 | J35: 10 | K35: API-Gateway | L35: Low | M35: VULN-6737688 | N35: Apply vendor patch immediately; isolate host from network if patch unavailable within 24h. | O35: ='Exec Summary'!$E$2-H35 -> 173 | P35: =IF(I35="","",I35-H35) -> 17 | Q35: =VLOOKUP(G35,$AA$2:$AB$5,2,FALSE()) -> 15 | R35: =IF(OR(F35="Open",F35="Reopened"),1,0) -> 0 | S35: =IF(AND(H35>='Exec Summary'!$E$1,H35<='Exec Summary'!$E$2),1,0) -> 0 | T35: =IF(AND(F35="Closed",I35<>"",I35>='Exec Summary'!$E$1,I35<='Exec Summary'!$E$2),1,0) -> 0 | U35: =IF(F35="Reopened",1,0) -> 0 | V35: =IF(AND(R35=1,O35>Q35),1,0) -> 0 | W35: =IF(AND(T35=1,P35<>"",P35<=Q35),1,0) -> 0
A36: APIGATEWAY-0109 | B36: Workstation | C36: Windows 11 | D36: PHP | E36: CVE-2024-4577 | F36: Closed | G36: Critical | H36: 45972 | I36: 45985 | J36: 9.8 | K36: API-Gateway | L36: Low | M36: VULN-5514342 | N36: Apply vendor patch immediately; isolate host from network if patch unavailable within 24h. | O36: ='Exec Summary'!$E$2-H36 -> 262 | P36: =IF(I36="","",I36-H36) -> 13 | Q36: =VLOOKUP(G36,$AA$2:$AB$5,2,FALSE()) -> 15 | R36: =IF(OR(F36="Open",F36="Reopened"),1,0) -> 0 | S36: =IF(AND(H36>='Exec Summary'!$E$1,H36<='Exec Summary'!$E$2),1,0) -> 0 | T36: =IF(AND(F36="Closed",I36<>"",I36>='Exec Summary'!$E$1,I36<='Exec Summary'!$E$2),1,0) -> 0 | U36: =IF(F36="Reopened",1,0) -> 0 | V36: =IF(AND(R36=1,O36>Q36),1,0) -> 0 | W36: =IF(AND(T36=1,P36<>"",P36<=Q36),1,0) -> 0
A37: APIGATEWAY-0109 | B37: Workstation | C37: Windows 11 | D37: Microsoft Outlook | E37: CVE-2024-21413 | F37: Open | G37: Critical | H37: 46027 | J37: 9.8 | K37: API-Gateway | L37: Low | M37: VULN-4190481 | N37: Apply vendor patch immediately; isolate host from network if patch unavailable within 24h. | O37: ='Exec Summary'!$E$2-H37 -> 207 | P37: =IF(I37="","",I37-H37) | Q37: =VLOOKUP(G37,$AA$2:$AB$5,2,FALSE()) -> 15 | R37: =IF(OR(F37="Open",F37="Reopened"),1,0) -> 1 | S37: =IF(AND(H37>='Exec Summary'!$E$1,H37<='Exec Summary'!$E$2),1,0) -> 0 | T37: =IF(AND(F37="Closed",I37<>"",I37>='Exec Summary'!$E$1,I37<='Exec Summary'!$E$2),1,0) -> 0 | U37: =IF(F37="Reopened",1,0) -> 0 | V37: =IF(AND(R37=1,O37>Q37),1,0) -> 1 | W37: =IF(AND(T37=1,P37<>"",P37<=Q37),1,0) -> 0
A38: APIGATEWAY-0109 | B38: Workstation | C38: Windows 11 | D38: libwebp | E38: CVE-2023-4863 | F38: Open | G38: High | H38: 46189 | J38: 8.8 | K38: API-Gateway | L38: Low | M38: VULN-4940319 | N38: Schedule patch within next maintenance window; apply compensating WAF/firewall rule if delayed. | O38: ='Exec Summary'!$E$2-H38 -> 45 | P38: =IF(I38="","",I38-H38) | Q38: =VLOOKUP(G38,$AA$2:$AB$5,2,FALSE()) -> 30 | R38: =IF(OR(F38="Open",F38="Reopened"),1,0) -> 1 | S38: =IF(AND(H38>='Exec Summary'!$E$1,H38<='Exec Summary'!$E$2),1,0) -> 0 | T38: =IF(AND(F38="Closed",I38<>"",I38>='Exec Summary'!$E$1,I38<='Exec Summary'!$E$2),1,0) -> 0 | U38: =IF(F38="Reopened",1,0) -> 0 | V38: =IF(AND(R38=1,O38>Q38),1,0) -> 1 | W38: =IF(AND(T38=1,P38<>"",P38<=Q38),1,0) -> 0
A39: APIGATEWAY-0109 | B39: Workstation | C39: Windows 11 | D39: nginx | E39: CVE-2023-44487 | F39: Open | G39: High | H39: 46057 | J39: 7.5 | K39: API-Gateway | L39: Low | M39: VULN-4469169 | N39: Schedule patch within next maintenance window; apply compensating WAF/firewall rule if delayed. | O39: ='Exec Summary'!$E$2-H39 -> 177 | P39: =IF(I39="","",I39-H39) | Q39: =VLOOKUP(G39,$AA$2:$AB$5,2,FALSE()) -> 30 | R39: =IF(OR(F39="Open",F39="Reopened"),1,0) -> 1 | S39: =IF(AND(H39>='Exec Summary'!$E$1,H39<='Exec Summary'!$E$2),1,0) -> 0 | T39: =IF(AND(F39="Closed",I39<>"",I39>='Exec Summary'!$E$1,I39<='Exec Summary'!$E$2),1,0) -> 0 | U39: =IF(F39="Reopened",1,0) -> 0 | V39: =IF(AND(R39=1,O39>Q39),1,0) -> 1 | W39: =IF(AND(T39=1,P39<>"",P39<=Q39),1,0) -> 0
A40: APIGATEWAY-0109 | B40: Workstation | C40: Windows 11 | D40: Apache ActiveMQ | E40: CVE-2023-46604 | F40: Closed | G40: Critical | H40: 46051 | I40: 46067 | J40: 9.8 | K40: API-Gateway | L40: Low | M40: VULN-6973148 | N40: Apply vendor patch immediately; isolate host from network if patch unavailable within 24h. | O40: ='Exec Summary'!$E$2-H40 -> 183 | P40: =IF(I40="","",I40-H40) -> 16 | Q40: =VLOOKUP(G40,$AA$2:$AB$5,2,FALSE()) -> 15 | R40: =IF(OR(F40="Open",F40="Reopened"),1,0) -> 0 | S40: =IF(AND(H40>='Exec Summary'!$E$1,H40<='Exec Summary'!$E$2),1,0) -> 0 | T40: =IF(AND(F40="Closed",I40<>"",I40>='Exec Summary'!$E$1,I40<='Exec Summary'!$E$2),1,0) -> 0 | U40: =IF(F40="Reopened",1,0) -> 0 | V40: =IF(AND(R40=1,O40>Q40),1,0) -> 0 | W40: =IF(AND(T40=1,P40<>"",P40<=Q40),1,0) -> 0
...

Sheet Tag Leaderboard
A1: Performance by Tag / Project
A3: Tags | B3: Hosts | C3: New | D3: Remediated | E3: Remediation Rate % | F3: Currently Open | G3: Reopened | H3: Open Critical | I3: SLA Breaches | J3: Avg Days to Close
A4: API-Gateway | B4: 41 | C4: =SUMIFS(All_Findings_Raw!$S$2:$S$4274,All_Findings_Raw!$K$2:$K$4274,A4) -> 22 | D4: =SUMIFS(All_Findings_Raw!$T$2:$T$4274,All_Findings_Raw!$K$2:$K$4274,A4) -> 26 | E4: =IFERROR(D4/(D4+F4)*100,0) -> 15.028902 | F4: =SUMIFS(All_Findings_Raw!$R$2:$R$4274,All_Findings_Raw!$K$2:$K$4274,A4) -> 147 | G4: =SUMIFS(All_Findings_Raw!$U$2:$U$4274,All_Findings_Raw!$K$2:$K$4274,A4) -> 18 | H4: =SUMIFS(All_Findings_Raw!$R$2:$R$4274,All_Findings_Raw!$K$2:$K$4274,A4,All_Findings_Raw!$G$2:$G$4274,"Critical") -> 94 | I4: =SUMIFS(All_Findings_Raw!$V$2:$V$4274,All_Findings_Raw!$K$2:$K$4274,A4) -> 143 | J4: =IFERROR(AVERAGEIFS(All_Findings_Raw!$P$2:$P$4274,All_Findings_Raw!$T$2:$T$4274,1,All_Findings_Raw!$K$2:$K$4274,A4),0) -> 19.538462
A5: Customer-Portal | B5: 33 | C5: =SUMIFS(All_Findings_Raw!$S$2:$S$4274,All_Findings_Raw!$K$2:$K$4274,A5) -> 15 | D5: =SUMIFS(All_Findings_Raw!$T$2:$T$4274,All_Findings_Raw!$K$2:$K$4274,A5) -> 9 | E5: =IFERROR(D5/(D5+F5)*100,0) -> 7.5630252 | F5: =SUMIFS(All_Findings_Raw!$R$2:$R$4274,All_Findings_Raw!$K$2:$K$4274,A5) -> 110 | G5: =SUMIFS(All_Findings_Raw!$U$2:$U$4274,All_Findings_Raw!$K$2:$K$4274,A5) -> 11 | H5: =SUMIFS(All_Findings_Raw!$R$2:$R$4274,All_Findings_Raw!$K$2:$K$4274,A5,All_Findings_Raw!$G$2:$G$4274,"Critical") -> 75 | I5: =SUMIFS(All_Findings_Raw!$V$2:$V$4274,All_Findings_Raw!$K$2:$K$4274,A5) -> 106 | J5: =IFERROR(AVERAGEIFS(All_Findings_Raw!$P$2:$P$4274,All_Findings_Raw!$T$2:$T$4274,1,All_Findings_Raw!$K$2:$K$4274,A5),0) -> 12.111111
A6: Data-Platform | B6: 31 | C6: =SUMIFS(All_Findings_Raw!$S$2:$S$4274,All_Findings_Raw!$K$2:$K$4274,A6) -> 14 | D6: =SUMIFS(All_Findings_Raw!$T$2:$T$4274,All_Findings_Raw!$K$2:$K$4274,A6) -> 14 | E6: =IFERROR(D6/(D6+F6)*100,0) -> 11.111111 | F6: =SUMIFS(All_Findings_Raw!$R$2:$R$4274,All_Findings_Raw!$K$2:$K$4274,A6) -> 112 | G6: =SUMIFS(All_Findings_Raw!$U$2:$U$4274,All_Findings_Raw!$K$2:$K$4274,A6) -> 12 | H6: =SUMIFS(All_Findings_Raw!$R$2:$R$4274,All_Findings_Raw!$K$2:$K$4274,A6,All_Findings_Raw!$G$2:$G$4274,"Critical") -> 69 | I6: =SUMIFS(All_Findings_Raw!$V$2:$V$4274,All_Findings_Raw!$K$2:$K$4274,A6) -> 106 | J6: =IFERROR(AVERAGEIFS(All_Findings_Raw!$P$2:$P$4274,All_Findings_Raw!$T$2:$T$4274,1,All_Findings_Raw!$K$2:$K$4274,A6),0) -> 22.642857
A7: DevOps-Tooling | B7: 18 | C7: =SUMIFS(All_Findings_Raw!$S$2:$S$4274,All_Findings_Raw!$K$2:$K$4274,A7) -> 11 | D7: =SUMIFS(All_Findings_Raw!$T$2:$T$4274,All_Findings_Raw!$K$2:$K$4274,A7) -> 10 | E7: =IFERROR(D7/(D7+F7)*100,0) -> 12.987013 | F7: =SUMIFS(All_Findings_Raw!$R$2:$R$4274,All_Findings_Raw!$K$2:$K$4274,A7) -> 67 | G7: =SUMIFS(All_Findings_Raw!$U$2:$U$4274,All_Findings_Raw!$K$2:$K$4274,A7) -> 6 | H7: =SUMIFS(All_Findings_Raw!$R$2:$R$4274,All_Findings_Raw!$K$2:$K$4274,A7,All_Findings_Raw!$G$2:$G$4274,"Critical") -> 41 | I7: =SUMIFS(All_Findings_Raw!$V$2:$V$4274,All_Findings_Raw!$K$2:$K$4274,A7) -> 64 | J7: =IFERROR(AVERAGEIFS(All_Findings_Raw!$P$2:$P$4274,All_Findings_Raw!$T$2:$T$4274,1,All_Findings_Raw!$K$2:$K$4274,A7),0) -> 17.1
A8: Finance-Systems | B8: 24 | C8: =SUMIFS(All_Findings_Raw!$S$2:$S$4274,All_Findings_Raw!$K$2:$K$4274,A8) -> 12 | D8: =SUMIFS(All_Findings_Raw!$T$2:$T$4274,All_Findings_Raw!$K$2:$K$4274,A8) -> 15 | E8: =IFERROR(D8/(D8+F8)*100,0) -> 15.625 | F8: =SUMIFS(All_Findings_Raw!$R$2:$R$4274,All_Findings_Raw!$K$2:$K$4274,A8) -> 81 | G8: =SUMIFS(All_Findings_Raw!$U$2:$U$4274,All_Findings_Raw!$K$2:$K$4274,A8) -> 15 | H8: =SUMIFS(All_Findings_Raw!$R$2:$R$4274,All_Findings_Raw!$K$2:$K$4274,A8,All_Findings_Raw!$G$2:$G$4274,"Critical") -> 48 | I8: =SUMIFS(All_Findings_Raw!$V$2:$V$4274,All_Findings_Raw!$K$2:$K$4274,A8) -> 79 | J8: =IFERROR(AVERAGEIFS(All_Findings_Raw!$P$2:$P$4274,All_Findings_Raw!$T$2:$T$4274,1,All_Findings_Raw!$K$2:$K$4274,A8),0) -> 27.266667
A9: HR-Systems | B9: 43 | C9: =SUMIFS(All_Findings_Raw!$S$2:$S$4274,All_Findings_Raw!$K$2:$K$4274,A9) -> 28 | D9: =SUMIFS(All_Findings_Raw!$T$2:$T$4274,All_Findings_Raw!$K$2:$K$4274,A9) -> 20 | E9: =IFERROR(D9/(D9+F9)*100,0) -> 12.5 | F9: =SUMIFS(All_Findings_Raw!$R$2:$R$4274,All_Findings_Raw!$K$2:$K$4274,A9) -> 140 | G9: =SUMIFS(All_Findings_Raw!$U$2:$U$4274,All_Findings_Raw!$K$2:$K$4274,A9) -> 15 | H9: =SUMIFS(All_Findings_Raw!$R$2:$R$4274,All_Findings_Raw!$K$2:$K$4274,A9,All_Findings_Raw!$G$2:$G$4274,"Critical") -> 86 | I9: =SUMIFS(All_Findings_Raw!$V$2:$V$4274,All_Findings_Raw!$K$2:$K$4274,A9) -> 133 | J9: =IFERROR(AVERAGEIFS(All_Findings_Raw!$P$2:$P$4274,All_Findings_Raw!$T$2:$T$4274,1,All_Findings_Raw!$K$2:$K$4274,A9),0) -> 23.3
A10: Identity-Auth | B10: 29 | C10: =SUMIFS(All_Findings_Raw!$S$2:$S$4274,All_Findings_Raw!$K$2:$K$4274,A10) -> 14 | D10: =SUMIFS(All_Findings_Raw!$T$2:$T$4274,All_Findings_Raw!$K$2:$K$4274,A10) -> 12 | E10: =IFERROR(D10/(D10+F10)*100,0) -> 10 | F10: =SUMIFS(All_Findings_Raw!$R$2:$R$4274,All_Findings_Raw!$K$2:$K$4274,A10) -> 108 | G10: =SUMIFS(All_Findings_Raw!$U$2:$U$4274,All_Findings_Raw!$K$2:$K$4274,A10) -> 13 | H10: =SUMIFS(All_Findings_Raw!$R$2:$R$4274,All_Findings_Raw!$K$2:$K$4274,A10,All_Findings_Raw!$G$2:$G$4274,"Critical") -> 62 | I10: =SUMIFS(All_Findings_Raw!$V$2:$V$4274,All_Findings_Raw!$K$2:$K$4274,A10) -> 102 | J10: =IFERROR(AVERAGEIFS(All_Findings_Raw!$P$2:$P$4274,All_Findings_Raw!$T$2:$T$4274,1,All_Findings_Raw!$K$2:$K$4274,A10),0) -> 20
A11: Internal-Tools | B11: 39 | C11: =SUMIFS(All_Findings_Raw!$S$2:$S$4274,All_Findings_Raw!$K$2:$K$4274,A11) -> 12 | D11: =SUMIFS(All_Findings_Raw!$T$2:$T$4274,All_Findings_Raw!$K$2:$K$4274,A11) -> 15 | E11: =IFERROR(D11/(D11+F11)*100,0) -> 11.627907 | F11: =SUMIFS(All_Findings_Raw!$R$2:$R$4274,All_Findings_Raw!$K$2:$K$4274,A11) -> 114 | G11: =SUMIFS(All_Findings_Raw!$U$2:$U$4274,All_Findings_Raw!$K$2:$K$4274,A11) -> 17 | H11: =SUMIFS(All_Findings_Raw!$R$2:$R$4274,All_Findings_Raw!$K$2:$K$4274,A11,All_Findings_Raw!$G$2:$G$4274,"Critical") -> 77 | I11: =SUMIFS(All_Findings_Raw!$V$2:$V$4274,All_Findings_Raw!$K$2:$K$4274,A11) -> 110 | J11: =IFERROR(AVERAGEIFS(All_Findings_Raw!$P$2:$P$4274,All_Findings_Raw!$T$2:$T$4274,1,All_Findings_Raw!$K$2:$K$4274,A11),0) -> 12.8
A12: Legacy-Systems | B12: 44 | C12: =SUMIFS(All_Findings_Raw!$S$2:$S$4274,All_Findings_Raw!$K$2:$K$4274,A12) -> 21 | D12: =SUMIFS(All_Findings_Raw!$T$2:$T$4274,All_Findings_Raw!$K$2:$K$4274,A12) -> 24 | E12: =IFERROR(D12/(D12+F12)*100,0) -> 12.631579 | F12: =SUMIFS(All_Findings_Raw!$R$2:$R$4274,All_Findings_Raw!$K$2:$K$4274,A12) -> 166 | G12: =SUMIFS(All_Findings_Raw!$U$2:$U$4274,All_Findings_Raw!$K$2:$K$4274,A12) -> 22 | H12: =SUMIFS(All_Findings_Raw!$R$2:$R$4274,All_Findings_Raw!$K$2:$K$4274,A12,All_Findings_Raw!$G$2:$G$4274,"Critical") -> 108 | I12: =SUMIFS(All_Findings_Raw!$V$2:$V$4274,All_Findings_Raw!$K$2:$K$4274,A12) -> 160 | J12: =IFERROR(AVERAGEIFS(All_Findings_Raw!$P$2:$P$4274,All_Findings_Raw!$T$2:$T$4274,1,All_Findings_Raw!$K$2:$K$4274,A12),0) -> 19.458333
A13: ML-Infrastructure | B13: 39 | C13: =SUMIFS(All_Findings_Raw!$S$2:$S$4274,All_Findings_Raw!$K$2:$K$4274,A13) -> 22 | D13: =SUMIFS(All_Findings_Raw!$T$2:$T$4274,All_Findings_Raw!$K$2:$K$4274,A13) -> 18 | E13: =IFERROR(D13/(D13+F13)*100,0) -> 10.11236 | F13: =SUMIFS(All_Findings_Raw!$R$2:$R$4274,All_Findings_Raw!$K$2:$K$4274,A13) -> 160 | G13: =SUMIFS(All_Findings_Raw!$U$2:$U$4274,All_Findings_Raw!$K$2:$K$4274,A13) -> 21 | H13: =SUMIFS(All_Findings_Raw!$R$2:$R$4274,All_Findings_Raw!$K$2:$K$4274,A13,All_Findings_Raw!$G$2:$G$4274,"Critical") -> 112 | I13: =SUMIFS(All_Findings_Raw!$V$2:$V$4274,All_Findings_Raw!$K$2:$K$4274,A13) -> 155 | J13: =IFERROR(AVERAGEIFS(All_Findings_Raw!$P$2:$P$4274,All_Findings_Raw!$T$2:$T$4274,1,All_Findings_Raw!$K$2:$K$4274,A13),0) -> 12.111111
A14: Marketing-Stack | B14: 42 | C14: =SUMIFS(All_Findings_Raw!$S$2:$S$4274,All_Findings_Raw!$K$2:$K$4274,A14) -> 23 | D14: =SUMIFS(All_Findings_Raw!$T$2:$T$4274,All_Findings_Raw!$K$2:$K$4274,A14) -> 19 | E14: =IFERROR(D14/(D14+F14)*100,0) -> 10.734463 | F14: =SUMIFS(All_Findings_Raw!$R$2:$R$4274,All_Findings_Raw!$K$2:$K$4274,A14) -> 158 | G14: =SUMIFS(All_Findings_Raw!$U$2:$U$4274,All_Findings_Raw!$K$2:$K$4274,A14) -> 19 | H14: =SUMIFS(All_Findings_Raw!$R$2:$R$4274,All_Findings_Raw!$K$2:$K$4274,A14,All_Findings_Raw!$G$2:$G$4274,"Critical") -> 102 | I14: =SUMIFS(All_Findings_Raw!$V$2:$V$4274,All_Findings_Raw!$K$2:$K$4274,A14) -> 148 | J14: =IFERROR(AVERAGEIFS(All_Findings_Raw!$P$2:$P$4274,All_Findings_Raw!$T$2:$T$4274,1,All_Findings_Raw!$K$2:$K$4274,A14),0) -> 22.052632
A15: Mobile-Backend | B15: 28 | C15: =SUMIFS(All_Findings_Raw!$S$2:$S$4274,All_Findings_Raw!$K$2:$K$4274,A15) -> 8 | D15: =SUMIFS(All_Findings_Raw!$T$2:$T$4274,All_Findings_Raw!$K$2:$K$4274,A15) -> 10 | E15: =IFERROR(D15/(D15+F15)*100,0) -> 9.6153846 | F15: =SUMIFS(All_Findings_Raw!$R$2:$R$4274,All_Findings_Raw!$K$2:$K$4274,A15) -> 94 | G15: =SUMIFS(All_Findings_Raw!$U$2:$U$4274,All_Findings_Raw!$K$2:$K$4274,A15) -> 12 | H15: =SUMIFS(All_Findings_Raw!$R$2:$R$4274,All_Findings_Raw!$K$2:$K$4274,A15,All_Findings_Raw!$G$2:$G$4274,"Critical") -> 56 | I15: =SUMIFS(All_Findings_Raw!$V$2:$V$4274,All_Findings_Raw!$K$2:$K$4274,A15) -> 93 | J15: =IFERROR(AVERAGEIFS(All_Findings_Raw!$P$2:$P$4274,All_Findings_Raw!$T$2:$T$4274,1,All_Findings_Raw!$K$2:$K$4274,A15),0) -> 19.4
... A18: Web-Frontend | B18: 29 | C18: =SUMIFS(All_Findings_Raw!$S$2:$S$4274,All_Findings_Raw!$K$2:$K$4274,A18) -> 16 | D18: =SUMIFS(All_Findings_Raw!$T$2:$T$4274,All_Findings_Raw!$K$2:$K$4274,A18) -> 11 | E18: =IFERROR(D18/(D18+F18)*100,0) -> 7.7464789 | F18: =SUMIFS(All_Findings_Raw!$R$2:$R$4274,All_Findings_Raw!$K$2:$K$4274,A18) -> 131 | G18: =SUMIFS(All_Findings_Raw!$U$2:$U$4274,All_Findings_Raw!$K$2:$K$4274,A18) -> 12 | H18: =SUMIFS(All_Findings_Raw!$R$2:$R$4274,All_Findings_Raw!$K$2:$K$4274,A18,All_Findings_Raw!$G$2:$G$4274,"Critical") -> 79 | I18: =SUMIFS(All_Findings_Raw!$V$2:$V$4274,All_Findings_Raw!$K$2:$K$4274,A18) -> 123 | J18: =IFERROR(AVERAGEIFS(All_Findings_Raw!$P$2:$P$4274,All_Findings_Raw!$T$2:$T$4274,1,All_Findings_Raw!$K$2:$K$4274,A18),0) -> 16.454545

Sheet Aging Analysis
A1: Aging of Currently-Open Findings
A3: Age Bucket | B3: All Open | C3: Critical | D3: High
A4: 0-30 days | B4: =COUNTIFS(All_Findings_Raw!$R$2:$R$4274,1,All_Findings_Raw!$O$2:$O$4274,">=0",All_Findings_Raw!$O$2:$O$4274,"<=30") -> 121 | C4: =COUNTIFS(All_Findings_Raw!$R$2:$R$4274,1,All_Findings_Raw!$O$2:$O$4274,">=0",All_Findings_Raw!$O$2:$O$4274,"<=30",All_Findings_Raw!$G$2:$G$4274,"Critical") -> 83 | D4: =COUNTIFS(All_Findings_Raw!$R$2:$R$4274,1,All_Findings_Raw!$O$2:$O$4274,">=0",All_Findings_Raw!$O$2:$O$4274,"<=30",All_Findings_Raw!$G$2:$G$4274,"High") -> 35
A5: 31-60 days | B5: =COUNTIFS(All_Findings_Raw!$R$2:$R$4274,1,All_Findings_Raw!$O$2:$O$4274,">=31",All_Findings_Raw!$O$2:$O$4274,"<=60") -> 180 | C5: =COUNTIFS(All_Findings_Raw!$R$2:$R$4274,1,All_Findings_Raw!$O$2:$O$4274,">=31",All_Findings_Raw!$O$2:$O$4274,"<=60",All_Findings_Raw!$G$2:$G$4274,"Critical") -> 115 | D5: =COUNTIFS(All_Findings_Raw!$R$2:$R$4274,1,All_Findings_Raw!$O$2:$O$4274,">=31",All_Findings_Raw!$O$2:$O$4274,"<=60",All_Findings_Raw!$G$2:$G$4274,"High") -> 58
A6: 61-90 days | B6: =COUNTIFS(All_Findings_Raw!$R$2:$R$4274,1,All_Findings_Raw!$O$2:$O$4274,">=61",All_Findings_Raw!$O$2:$O$4274,"<=90") -> 193 | C6: =COUNTIFS(All_Findings_Raw!$R$2:$R$4274,1,All_Findings_Raw!$O$2:$O$4274,">=61",All_Findings_Raw!$O$2:$O$4274,"<=90",All_Findings_Raw!$G$2:$G$4274,"Critical") -> 120 | D6: =COUNTIFS(All_Findings_Raw!$R$2:$R$4274,1,All_Findings_Raw!$O$2:$O$4274,">=61",All_Findings_Raw!$O$2:$O$4274,"<=90",All_Findings_Raw!$G$2:$G$4274,"High") -> 68
A7: 90+ days | B7: =COUNTIFS(All_Findings_Raw!$R$2:$R$4274,1,All_Findings_Raw!$O$2:$O$4274,">=91") -> 1323 | C7: =COUNTIFS(All_Findings_Raw!$R$2:$R$4274,1,All_Findings_Raw!$O$2:$O$4274,">=91",All_Findings_Raw!$G$2:$G$4274,"Critical") -> 829 | D7: =COUNTIFS(All_Findings_Raw!$R$2:$R$4274,1,All_Findings_Raw!$O$2:$O$4274,">=91",All_Findings_Raw!$G$2:$G$4274,"High") -> 448

Sheet Top Risks
A1: Risk Concentration
A3: Top Hosts by Open Critical + High Findings
A4: Hostname | B4: Tags | C4: Open Critical | D4: Open High | E4: Total
A5: HRSYSTEMS-0391 | B5: HR-Systems | C5: =SUMIFS(All_Findings_Raw!$R$2:$R$4274,All_Findings_Raw!$A$2:$A$4274,A5,All_Findings_Raw!$G$2:$G$4274,"Critical") -> 6 | D5: =SUMIFS(All_Findings_Raw!$R$2:$R$4274,All_Findings_Raw!$A$2:$A$4274,A5,All_Findings_Raw!$G$2:$G$4274,"High") -> 6 | E5: =C5+D5 -> 12
A6: PAYMENTSPROD-0023 | B6: Payments-Prod | C6: =SUMIFS(All_Findings_Raw!$R$2:$R$4274,All_Findings_Raw!$A$2:$A$4274,A6,All_Findings_Raw!$G$2:$G$4274,"Critical") -> 7 | D6: =SUMIFS(All_Findings_Raw!$R$2:$R$4274,All_Findings_Raw!$A$2:$A$4274,A6,All_Findings_Raw!$G$2:$G$4274,"High") -> 4 | E6: =C6+D6 -> 11
A7: LEGACYSYSTEMS-0497 | B7: Legacy-Systems | C7: =SUMIFS(All_Findings_Raw!$R$2:$R$4274,All_Findings_Raw!$A$2:$A$4274,A7,All_Findings_Raw!$G$2:$G$4274,"Critical") -> 6 | D7: =SUMIFS(All_Findings_Raw!$R$2:$R$4274,All_Findings_Raw!$A$2:$A$4274,A7,All_Findings_Raw!$G$2:$G$4274,"High") -> 5 | E7: =C7+D7 -> 11
A8: APIGATEWAY-0116 | B8: API-Gateway | C8: =SUMIFS(All_Findings_Raw!$R$2:$R$4274,All_Findings_Raw!$A$2:$A$4274,A8,All_Findings_Raw!$G$2:$G$4274,"Critical") -> 6 | D8: =SUMIFS(All_Findings_Raw!$R$2:$R$4274,All_Findings_Raw!$A$2:$A$4274,A8,All_Findings_Raw!$G$2:$G$4274,"High") -> 4 | E8: =C8+D8 -> 10
A9: DATAPLATFORM-0175 | B9: Data-Platform | C9: =SUMIFS(All_Findings_Raw!$R$2:$R$4274,All_Findings_Raw!$A$2:$A$4274,A9,All_Findings_Raw!$G$2:$G$4274,"Critical") -> 7 | D9: =SUMIFS(All_Findings_Raw!$R$2:$R$4274,All_Findings_Raw!$A$2:$A$4274,A9,All_Findings_Raw!$G$2:$G$4274,"High") -> 2 | E9: =C9+D9 -> 9
A10: LEGACYSYSTEMS-0495 | B10: Legacy-Systems | C10: =SUMIFS(All_Findings_Raw!$R$2:$R$4274,All_Findings_Raw!$A$2:$A$4274,A10,All_Findings_Raw!$G$2:$G$4274,"Critical") -> 7 | D10: =SUMIFS(All_Findings_Raw!$R$2:$R$4274,All_Findings_Raw!$A$2:$A$4274,A10,All_Findings_Raw!$G$2:$G$4274,"High") -> 2 | E10: =C10+D10 -> 9
A11: WEBFRONTEND-0090 | B11: Web-Frontend | C11: =SUMIFS(All_Findings_Raw!$R$2:$R$4274,All_Findings_Raw!$A$2:$A$4274,A11,All_Findings_Raw!$G$2:$G$4274,"Critical") -> 4 | D11: =SUMIFS(All_Findings_Raw!$R$2:$R$4274,All_Findings_Raw!$A$2:$A$4274,A11,All_Findings_Raw!$G$2:$G$4274,"High") -> 5 | E11: =C11+D11 -> 9
A12: FINANCESYSTEMS-0357 | B12: Finance-Systems | C12: =SUMIFS(All_Findings_Raw!$R$2:$R$4274,All_Findings_Raw!$A$2:$A$4274,A12,All_Findings_Raw!$G$2:$G$4274,"Critical") -> 5 | D12: =SUMIFS(All_Findings_Raw!$R$2:$R$4274,All_Findings_Raw!$A$2:$A$4274,A12,All_Findings_Raw!$G$2:$G$4274,"High") -> 4 | E12: =C12+D12 -> 9
A13: INTERNALTOOLS-0254 | B13: Internal-Tools | C13: =SUMIFS(All_Findings_Raw!$R$2:$R$4274,All_Findings_Raw!$A$2:$A$4274,A13,All_Findings_Raw!$G$2:$G$4274,"Critical") -> 4 | D13: =SUMIFS(All_Findings_Raw!$R$2:$R$4274,All_Findings_Raw!$A$2:$A$4274,A13,All_Findings_Raw!$G$2:$G$4274,"High") -> 5 | E13: =C13+D13 -> 9
A14: WEBFRONTEND-0084 | B14: Web-Frontend | C14: =SUMIFS(All_Findings_Raw!$R$2:$R$4274,All_Findings_Raw!$A$2:$A$4274,A14,All_Findings_Raw!$G$2:$G$4274,"Critical") -> 5 | D14: =SUMIFS(All_Findings_Raw!$R$2:$R$4274,All_Findings_Raw!$A$2:$A$4274,A14,All_Findings_Raw!$G$2:$G$4274,"High") -> 4 | E14: =C14+D14 -> 9
A15: PAYMENTSPROD-0012 | B15: Payments-Prod | C15: =SUMIFS(All_Findings_Raw!$R$2:$R$4274,All_Findings_Raw!$A$2:$A$4274,A15,All_Findings_Raw!$G$2:$G$4274,"Critical") -> 5 | D15: =SUMIFS(All_Findings_Raw!$R$2:$R$4274,All_Findings_Raw!$A$2:$A$4274,A15,All_Findings_Raw!$G$2:$G$4274,"High") -> 4 | E15: =C15+D15 -> 9
A16: MOBILEBACKEND-0303 | B16: Mobile-Backend | C16: =SUMIFS(All_Findings_Raw!$R$2:$R$4274,All_Findings_Raw!$A$2:$A$4274,A16,All_Findings_Raw!$G$2:$G$4274,"Critical") -> 5 | D16: =SUMIFS(All_Findings_Raw!$R$2:$R$4274,All_Findings_Raw!$A$2:$A$4274,A16,All_Findings_Raw!$G$2:$G$4274,"High") -> 3 | E16: =C16+D16 -> 8
... A19: MARKETINGSTACK-0422 | B19: Marketing-Stack | C19: =SUMIFS(All_Findings_Raw!$R$2:$R$4274,All_Findings_Raw!$A$2:$A$4274,A19,All_Findings_Raw!$G$2:$G$4274,"Critical") -> 6 | D19: =SUMIFS(All_Findings_Raw!$R$2:$R$4274,All_Findings_Raw!$A$2:$A$4274,A19,All_Findings_Raw!$G$2:$G$4274,"High") -> 2 | E19: =C19+D19 -> 8
A22: Most Recurring CVEs (currently open, across hosts)
A23: CVE ID | B23: Severity | C23: Product | D23: # Hosts Affected
A24: CVE-2024-3400 | B24: Critical | C24: PAN-OS | D24: =SUMIFS(All_Findings_Raw!$R$2:$R$4274,All_Findings_Raw!$E$2:$E$4274,A24) -> 77
A25: CVE-2021-44228 | B25: Critical | C25: Apache Log4j | D25: =SUMIFS(All_Findings_Raw!$R$2:$R$4274,All_Findings_Raw!$E$2:$E$4274,A25) -> 74
A26: CVE-2023-20887 | B26: High | C26: VMware Aria Operations | D26: =SUMIFS(All_Findings_Raw!$R$2:$R$4274,All_Findings_Raw!$E$2:$E$4274,A26) -> 72
A27: CVE-2023-22515 | B27: Critical | C27: Atlassian Confluence | D27: =SUMIFS(All_Findings_Raw!$R$2:$R$4274,All_Findings_Raw!$E$2:$E$4274,A27) -> 69
A28: CVE-2023-46604 | B28: Critical | C28: Apache ActiveMQ | D28: =SUMIFS(All_Findings_Raw!$R$2:$R$4274,All_Findings_Raw!$E$2:$E$4274,A28) -> 66
A29: CVE-2023-36884 | B29: High | C29: Microsoft Office | D29: =SUMIFS(All_Findings_Raw!$R$2:$R$4274,All_Findings_Raw!$E$2:$E$4274,A29) -> 64
A30: CVE-2024-23897 | B30: Critical | C30: Jenkins | D30: =SUMIFS(All_Findings_Raw!$R$2:$R$4274,All_Findings_Raw!$E$2:$E$4274,A30) -> 63
A31: CVE-2023-29357 | B31: Critical | C31: Microsoft SharePoint Server | D31: =SUMIFS(All_Findings_Raw!$R$2:$R$4274,All_Findings_Raw!$E$2:$E$4274,A31) -> 63
A32: CVE-2023-34362 | B32: Critical | C32: MOVEit Transfer | D32: =SUMIFS(All_Findings_Raw!$R$2:$R$4274,All_Findings_Raw!$E$2:$E$4274,A32) -> 62
A33: CVE-2024-6670 | B33: High | C33: MySQL | D33: =SUMIFS(All_Findings_Raw!$R$2:$R$4274,All_Findings_Raw!$E$2:$E$4274,A33) -> 62

Sheet Methodology & Assumptions
A1: Methodology & Assumptions
A3: • Data source: 15 detailed CrowdStrike finding-level export file(s), one per tag/project, combined on the 'All_Findings_Raw' sheet.
A4: • Reporting period: 2026-07-01 to 2026-07-31 — set in cells E1/E2 on the Exec Summary sheet; every formula in this workbook references those two cells, so changing them recalculates the whole report.
A5: • New = Created Date within the period. Remediated = Status is Closed (not Reopened) AND Closed Date within the period — both exact, from CrowdStrike's own timestamps.
A6: • Reopened findings count as currently OPEN (active risk), not resolved. A finding closed then reopened does NOT count as a remediation win, even if Closed Date falls in this period.
A7: • SLA targets: Critical=15d, High=30d, Medium=90d, Low=180d — see the small lookup table on All_Findings_Raw (columns AA:AB). Edit there to change SLA policy; formulas update automatically.
A8: • All Exec Summary, Leaderboard, Aging, and Top Risks figures are LIVE FORMULAS (COUNTIFS/SUMIFS/AVERAGEIFS) referencing All_Findings_Raw — edit or add rows there and the rest of the workbook recalculates.
A9: • Exception: 'Hosts' (unique host count) per tag on the Leaderboard is computed once at report-generation time, not as a live formula — true unique-count formulas are unreliable across Excel/LibreOffice versions at this scale. Regenerate the report to refresh this figure after adding new hosts.
A10: • This report expects each input file to include BOTH open and closed findings (not just currently-open) — if a file only has open findings, New/Remediated totals will be understated.
